tests/smoke/.smoke/normalized_tail_preview.csv
ask_price_1_static_plgs,bid_price_1_static_plgs,ask_price_2_static_plgs,bid_price_2_static_plgs,ask_price_3_static_plgs,bid_price_3_static_plgs,ask_price_4_static_plgs,bid_price_4_static_plgs,ask_price_5_static_plgs,bid_price_5_static_plgs,ask_price_6_static_plgs,bid_price_6_static_plgs,ask_price_7_static_plgs,bid_price_7_static_plgs,ask_price_8_static_plgs,bid_price_8_static_plgs,ask_price_9_static_plgs,bid_price_9_static_plgs,ask_price_10_static_plgs,bid_price_10_static_plgs,ask_size_1_static_exp,bid_size_1_static_exp,ask_size_2_static_exp,bid_size_2_static_exp,ask_size_3_static_exp,bid_size_3_static_exp,ask_size_4_static_exp,bid_size_4_static_exp,ask_size_5_static_exp,bid_size_5_static_exp,ask_size_6_static_exp,bid_size_6_static_exp,ask_size_7_static_exp,bid_size_7_static_exp,ask_size_8_static_exp,bid_size_8_static_exp,ask_size_9_static_exp,bid_size_9_static_exp,ask_size_10_static_exp,bid_size_10_static_exp,ask_price_1_kin_pos,ask_price_1_kin_vel,ask_price_1_kin_acc,ask_price_1_kin_jrk,bid_price_1_kin_pos,bid_price_1_kin_vel,bid_price_1_kin_acc,bid_price_1_kin_jrk,ask_price_2_kin_pos,ask_price_2_kin_vel,ask_price_2_kin_acc,ask_price_2_kin_jrk,bid_price_2_kin_pos,bid_price_2_kin_vel,bid_price_2_kin_acc,bid_price_2_kin_jrk,ask_price_3_kin_pos,ask_price_3_kin_vel,ask_price_3_kin_acc,ask_price_3_kin_jrk,bid_price_3_kin_pos,bid_price_3_kin_vel,bid_price_3_kin_acc,bid_price_3_kin_jrk,ask_price_4_kin_pos,ask_price_4_kin_vel,ask_price_4_kin_acc,ask_price_4_kin_jrk,bid_price_4_kin_pos,bid_price_4_kin_vel,bid_price_4_kin_acc,bid_price_4_kin_jrk,ask_price_5_kin_pos,ask_price_5_kin_vel,ask_price_5_kin_acc,ask_price_5_kin_jrk,bid_price_5_kin_pos,bid_price_5_kin_vel,bid_price_5_kin_acc,bid_price_5_kin_jrk,ask_price_6_kin_pos,ask_price_6_kin_vel,ask_price_6_kin_acc,ask_price_6_kin_jrk,bid_price_6_kin_pos,bid_price_6_kin_vel,bid_price_6_kin_acc,bid_price_6_kin_jrk,ask_price_7_kin_pos,ask_price_7_kin_vel,ask_price_7_kin_acc,ask_price_7_kin_jrk,bid_price_7_kin_pos,bid_price_7_kin_vel,bid_price_7_kin_acc,bid_price_7_kin_jrk,ask_price_8_kin_pos,ask_price_8_kin_vel,ask_price_8_kin_acc,ask_price_8_kin_jrk,bid_price_8_kin_pos,bid_price_8_kin_vel,bid_price_8_kin_acc,bid_price_8_kin_jrk,ask_price_9_kin_pos,ask_price_9_kin_vel,ask_price_9_kin_acc,ask_price_9_kin_jrk,bid_price_9_kin_pos,bid_price_9_kin_vel,bid_price_9_kin_acc,bid_price_9_kin_jrk,ask_price_10_kin_pos,ask_price_10_kin_vel,ask_price_10_kin_acc,ask_price_10_kin_jrk,bid_price_10_kin_pos,bid_price_10_kin_vel,bid_price_10_kin_acc,bid_price_10_kin_jrk,ask_size_1_kin_pos,ask_size_1_kin_vel,ask_size_1_kin_acc,ask_size_1_kin_jrk,bid_size_1_kin_pos,bid_size_1_kin_vel,bid_size_1_kin_acc,bid_size_1_kin_jrk,ask_size_2_kin_pos,ask_size_2_kin_vel,ask_size_2_kin_acc,ask_size_2_kin_jrk,bid_size_2_kin_pos,bid_size_2_kin_vel,bid_size_2_kin_acc,bid_size_2_kin_jrk,ask_size_3_kin_pos,ask_size_3_kin_vel,ask_size_3_kin_acc,ask_size_3_kin_jrk,bid_size_3_kin_pos,bid_size_3_kin_vel,bid_size_3_kin_acc,bid_size_3_kin_jrk,ask_size_4_kin_pos,ask_size_4_kin_vel,ask_size_4_kin_acc,ask_size_4_kin_jrk,bid_size_4_kin_pos,bid_size_4_kin_vel,bid_size_4_kin_acc,bid_size_4_kin_jrk,ask_size_5_kin_pos,ask_size_5_kin_vel,ask_size_5_kin_acc,ask_size_5_kin_jrk,bid_size_5_kin_pos,bid_size_5_kin_vel,bid_size_5_kin_acc,bid_size_5_kin_jrk,ask_size_6_kin_pos,ask_size_6_kin_vel,ask_size_6_kin_acc,ask_size_6_kin_jrk,bid_size_6_kin_pos,bid_size_6_kin_vel,bid_size_6_kin_acc,bid_size_6_kin_jrk,ask_size_7_kin_pos,ask_size_7_kin_vel,ask_size_7_kin_acc,ask_size_7_kin_jrk,bid_size_7_kin_pos,bid_size_7_kin_vel,bid_size_7_kin_acc,bid_size_7_kin_jrk,ask_size_8_kin_pos,ask_size_8_kin_vel,ask_size_8_kin_acc,ask_size_8_kin_jrk,bid_size_8_kin_pos,bid_size_8_kin_vel,bid_size_8_kin_acc,bid_size_8_kin_jrk,ask_size_9_kin_pos,ask_size_9_kin_vel,ask_size_9_kin_acc,ask_size_9_kin_jrk,bid_size_9_kin_pos,bid_size_9_kin_vel,bid_size_9_kin_acc,bid_size_9_kin_jrk,ask_size_10_kin_pos,ask_size_10_kin_vel,ask_size_10_kin_acc,ask_size_10_kin_jrk,bid_size_10_kin_pos,bid_size_10_kin_vel,bid_size_10_kin_acc,bid_size_10_kin_jrk,time,delta_t,trend_label,size_log1p,price_static,type_1,type_2,type_3,type_4,type_5,direction_-1,direction_1,time_day_sin,time_day_cos
0.18367718339820627,0.20008526368292742,0.20008526368292742,0.20816521051441303,0.231918646535224,0.21616354172133806,0.2396770440449691,0.24735707390310074,0.26993483359356973,0.3602017001635879,0.27730922921383666,0.3980112596527733,0.35367314608362466,0.3980112596527733,0.3980112596527733,0.3980112596527733,0.3980112596527733,0.3980112596527733,0.3980112596527733,0.3980112596527733,0.048770575499285984,0.008959621227116354,0.048770575499285984,0.0024968776025399153,0.029069122358805766,0.009950166250831893,0.1392920235749422,0.0014988755622891148,0.18126924692201818,0.08010891332876358,0.048770575499285984,0.048770575499285984,0.09516258196404048,0.0024968776025399153,0.0024968776025399153,0.04352439990637924,0.09516258196404048,0.048770575499285984,0.024690087971667385,0.000999500166624978,10.5,0.00910667920390885,0.0032148081588972417,0.004902340365204072,-10.5,-0.0386942829490951,-7.105117669154883e-16,-7.018590255875503e-16,12.5,0.005192689979749926,-1.712834753038187e-15,0.0035082212752699793,-11.5,-0.040337555514995724,2.6469884850772603e-16,4.369636642287035e-16,16.5,0.0033049947747920715,0.004667428680014368,0.014150584245581363,-12.5,-0.03191407030814895,6.060653336357976e-16,6.045405390296513e-16,17.5,0.027178622056508884,0.04114982434390288,0.06523432228843283,-16.5,-0.030006309483850222,2.569285745422144e-16,4.0619457665492725e-16,21.5,-0.013161979402732735,-0.02185750766428321,-0.01585375679963929,-32.5,-3.377880794926321,-3.3186337141620226,-3.110783812193128,22.5,0.020211558139220775,-0.0009651354306681167,-0.0002106686895107615,-51.5,-3.3815512114827815,-3.4424577639762726,-3.4713609078668877,33.5,0.02334305761128961,3.737048941971016e-16,0.0012504663542260972,-66.5,-2.5975945613915825,-2.6629040953938903,-2.695162702843728,56.5,0.022277624218098344,0.0017335359279177158,0.005575038648114783,-75.5,-1.6001617086396698,-1.6766690626892773,-1.706525749986342,112.5,0.0018908032853270278,-0.0065194218011123215,-0.0009347821280936201,-76.5,-0.25576834733472564,-0.24354569124727665,-0.24821000018434647,118.5,0.007674288085723671,-0.00397874769910124,-0.00022464775602664802,-77.5,-0.2722761268379036,-0.2570136333956102,-0.2597040003470974,4.61512051684126,-0.008036971161465244,0.012588467594022738,0.019024014526950905,2.9444389791664403,-1.5856315699950725e-16,-5.844610776258461e-17,-9.262495265026694e-17,4.61512051684126,-0.029625991358974427,-0.021667115281042395,-0.016339889451409784,1.791759469228055,1.866281776115077e-16,2.5285884017768914e-16,2.8605204544929436e-16,4.0943445622221,0.009958509437169763,-6.925798955844703e-17,-2.2800353978790795e-16,3.044522437723423,0.005151219878528101,3.7878507292838385e-16,4.125373318624019e-16,5.707110264748875,-0.002275163860045194,0.001998677556016315,0.003038454903516609,1.3862943611198906,0.006232848691058176,1.3526745419539692e-16,1.5444633559002802e-16,5.993961427306569,-0.015838528359245287,-0.014699894088151439,-0.018681189423379787,5.123963979403259,0.8564762940692024,0.8909017807132181,0.9083242700602022,4.61512051684126,0.016134610916264547,0.014130947360589263,0.012459398018317214,4.61512051684126,-0.5892812087104704,-0.6110596834818391,-0.6199302598906913,5.303304908059076,-0.013432839743020395,-0.010459271332447229,-0.012881665966078414,1.791759469228055,-2.4709662402587473,-2.5485409920413784,-2.5848976809414417,1.791759469228055,0.03068140669531759,0.021267437322851974,0.021224284738268567,4.499809670330265,2.157609933028955,2.207453358191078,2.2298637943277333,5.303304908059076,-0.017033260717406525,-0.004977766072114833,0.0008606346746234627,4.61512051684126,0.10402282598827549,0.10488087197045584,0.10637363158006398,3.9318256327243257,-0.006150298110220255,-0.012485196661471569,-0.010899903928228184,1.0986122886681098,-2.868530607968785,-2.9537395669493485,-2.9859174683559324,34201.0316505,0.015481920003367122,0.0,4.61512051684126,-34.0,0.0,0.0,1.0,0.0,0.0,0.0,1.0,0.6087019069596477,-0.7933990096185453
