tests/smoke/.smoke/pipeline_processed/train/2012-06-21_processed.csv
ask_price_1_static_plgs,bid_price_1_static_plgs,ask_price_2_static_plgs,bid_price_2_static_plgs,ask_price_3_static_plgs,bid_price_3_static_plgs,ask_price_4_static_plgs,bid_price_4_static_plgs,ask_price_5_static_plgs,bid_price_5_static_plgs,ask_price_6_static_plgs,bid_price_6_static_plgs,ask_price_7_static_plgs,bid_price_7_static_plgs,ask_price_8_static_plgs,bid_price_8_static_plgs,ask_price_9_static_plgs,bid_price_9_static_plgs,ask_price_10_static_plgs,bid_price_10_static_plgs,ask_size_1_static_exp,bid_size_1_static_exp,ask_size_2_static_exp,bid_size_2_static_exp,ask_size_3_static_exp,bid_size_3_static_exp,ask_size_4_static_exp,bid_size_4_static_exp,ask_size_5_static_exp,bid_size_5_static_exp,ask_size_6_static_exp,bid_size_6_static_exp,ask_size_7_static_exp,bid_size_7_static_exp,ask_size_8_static_exp,bid_size_8_static_exp,ask_size_9_static_exp,bid_size_9_static_exp,ask_size_10_static_exp,bid_size_10_static_exp,ask_price_1_kin_pos,ask_price_1_kin_vel,ask_price_1_kin_acc,ask_price_1_kin_jrk,bid_price_1_kin_pos,bid_price_1_kin_vel,bid_price_1_kin_acc,bid_price_1_kin_jrk,ask_price_2_kin_pos,ask_price_2_kin_vel,ask_price_2_kin_acc,ask_price_2_kin_jrk,bid_price_2_kin_pos,bid_price_2_kin_vel,bid_price_2_kin_acc,bid_price_2_kin_jrk,ask_price_3_kin_pos,ask_price_3_kin_vel,ask_price_3_kin_acc,ask_price_3_kin_jrk,bid_price_3_kin_pos,bid_price_3_kin_vel,bid_price_3_kin_acc,bid_price_3_kin_jrk,ask_price_4_kin_pos,ask_price_4_kin_vel,ask_price_4_kin_acc,ask_price_4_kin_jrk,bid_price_4_kin_pos,bid_price_4_kin_vel,bid_price_4_kin_acc,bid_price_4_kin_jrk,ask_price_5_kin_pos,ask_price_5_kin_vel,ask_price_5_kin_acc,ask_price_5_kin_jrk,bid_price_5_kin_pos,bid_price_5_kin_vel,bid_price_5_kin_acc,bid_price_5_kin_jrk,ask_price_6_kin_pos,ask_price_6_kin_vel,ask_price_6_kin_acc,ask_price_6_kin_jrk,bid_price_6_kin_pos,bid_price_6_kin_vel,bid_price_6_kin_acc,bid_price_6_kin_jrk,ask_price_7_kin_pos,ask_price_7_kin_vel,ask_price_7_kin_acc,ask_price_7_kin_jrk,bid_price_7_kin_pos,bid_price_7_kin_vel,bid_price_7_kin_acc,bid_price_7_kin_jrk,ask_price_8_kin_pos,ask_price_8_kin_vel,ask_price_8_kin_acc,ask_price_8_kin_jrk,bid_price_8_kin_pos,bid_price_8_kin_vel,bid_price_8_kin_acc,bid_price_8_kin_jrk,ask_price_9_kin_pos,ask_price_9_kin_vel,ask_price_9_kin_acc,ask_price_9_kin_jrk,bid_price_9_kin_pos,bid_price_9_kin_vel,bid_price_9_kin_acc,bid_price_9_kin_jrk,ask_price_10_kin_pos,ask_price_10_kin_vel,ask_price_10_kin_acc,ask_price_10_kin_jrk,bid_price_10_kin_pos,bid_price_10_kin_vel,bid_price_10_kin_acc,bid_price_10_kin_jrk,ask_size_1_kin_pos,ask_size_1_kin_vel,ask_size_1_kin_acc,ask_size_1_kin_jrk,bid_size_1_kin_pos,bid_size_1_kin_vel,bid_size_1_kin_acc,bid_size_1_kin_jrk,ask_size_2_kin_pos,ask_size_2_kin_vel,ask_size_2_kin_acc,ask_size_2_kin_jrk,bid_size_2_kin_pos,bid_size_2_kin_vel,bid_size_2_kin_acc,bid_size_2_kin_jrk,ask_size_3_kin_pos,ask_size_3_kin_vel,ask_size_3_kin_acc,ask_size_3_kin_jrk,bid_size_3_kin_pos,bid_size_3_kin_vel,bid_size_3_kin_acc,bid_size_3_kin_jrk,ask_size_4_kin_pos,ask_size_4_kin_vel,ask_size_4_kin_acc,ask_size_4_kin_jrk,bid_size_4_kin_pos,bid_size_4_kin_vel,bid_size_4_kin_acc,bid_size_4_kin_jrk,ask_size_5_kin_pos,ask_size_5_kin_vel,ask_size_5_kin_acc,ask_size_5_kin_jrk,bid_size_5_kin_pos,bid_size_5_kin_vel,bid_size_5_kin_acc,bid_size_5_kin_jrk,ask_size_6_kin_pos,ask_size_6_kin_vel,ask_size_6_kin_acc,ask_size_6_kin_jrk,bid_size_6_kin_pos,bid_size_6_kin_vel,bid_size_6_kin_acc,bid_size_6_kin_jrk,ask_size_7_kin_pos,ask_size_7_kin_vel,ask_size_7_kin_acc,ask_size_7_kin_jrk,bid_size_7_kin_pos,bid_size_7_kin_vel,bid_size_7_kin_acc,bid_size_7_kin_jrk,ask_size_8_kin_pos,ask_size_8_kin_vel,ask_size_8_kin_acc,ask_size_8_kin_jrk,bid_size_8_kin_pos,bid_size_8_kin_vel,bid_size_8_kin_acc,bid_size_8_kin_jrk,ask_size_9_kin_pos,ask_size_9_kin_vel,ask_size_9_kin_acc,ask_size_9_kin_jrk,bid_size_9_kin_pos,bid_size_9_kin_vel,bid_size_9_kin_acc,bid_size_9_kin_jrk,ask_size_10_kin_pos,ask_size_10_kin_vel,ask_size_10_kin_acc,ask_size_10_kin_jrk,bid_size_10_kin_pos,bid_size_10_kin_vel,bid_size_10_kin_acc,bid_size_10_kin_jrk,time,delta_t,trend_label,size_log1p,price_static,type_1,type_2,type_3,type_4,type_5,direction_-1,direction_1,time_day_sin,time_day_cos
0.2918353063329953,0.30606940945026895,0.32688591827809516,0.3470779741048861,0.3404155044528951,0.37306163946241183,0.37306163946241183,0.3980112596527733,0.3980112596527733,0.3980112596527733,0.3980112596527733,0.3980112596527733,0.3980112596527733,0.3980112596527733,0.3980112596527733,0.3980112596527733,0.3980112596527733,0.3980112596527733,0.3980112596527733,0.3980112596527733,0.048770575499285984,0.09516258196404048,0.048770575499285984,0.048770575499285984,0.048770575499285984,0.048770575499285984,0.8496816649535996,0.048770575499285984,0.03197755016869397,0.048770575499285984,0.3934693402873666,0.09516258196404048,0.048770575499285984,0.048770575499285984,0.048770575499285984,0.048770575499285984,0.048770575499285984,0.09516258196404048,0.048770575499285984,0.048770575499285984,15.0,-0.000201617542433198,-0.00013743333401997394,-0.0002092943351119521,-20.0,-0.34578677556486853,-0.5990777972193073,-0.9147102504068377,20.0,-7.922009369960987e-16,-0.0010372048299495916,-0.0015735051922831974,-26.0,-1.9401218926485737,-1.314572029759502,-1.0956247499317684,22.0,-0.0014807035986611906,-0.0008499999784664047,-0.0012958930610643964,-30.0,-1.256557673211439,-1.060428577499871,-1.1189231968128028,27.0,-0.00040336904690424524,-0.0006938377347116857,-0.0010569715656245438,-39.0,-2.459980644916124,-1.776375025718093,-1.6023261084818896,32.0,0.0004780794312639295,-0.00040975133420041433,-0.0006238210313252657,-41.0,-1.3836187159258588,-1.596662708997301,-2.067007480836656,37.0,0.0010269145964315115,-0.0008816943014264811,-0.0013434061593124622,-48.0,-2.6371997790940305,-1.8203920246482046,-1.5581961281088041,41.0,0.0006151296489436177,-0.0005280530487986676,-0.0008048482302557759,-54.0,-2.290106555308417,-1.9067163649713346,-1.9907848732788542,45.0,0.0006392126253663418,-9.874899493793339e-05,-0.00014976193919170953,-56.0,-1.0174804986313446,-1.0624731321612864,-1.301458346067404,46.0,0.0005557050494420907,-0.0004753695284894767,-0.0007231130102253776,-60.0,-1.807725283338232,-1.3278851881665477,-1.2189641571887173,47.0,-6.503520056158599e-05,-0.0004444913597143468,-0.0006756828857288041,-61.0,-0.9269558341147279,-1.0329104338220827,-1.3130062962719111,4.61512051684126,-0.000658503787979356,-0.0011348560443583998,-0.0017284874655782631,5.303304908059076,-0.6304574097122597,-0.9352143727939495,-0.9493970522735453,4.61512051684126,-0.0007365035155215997,0.00018615249894776906,0.00028108724303440636,4.61512051684126,1.7914995796955285e-17,-1.4431215910627244e-16,-2.7927372266728503e-16,4.61512051684126,-0.0005411860989211819,-0.0004490909794460018,-0.0008316773577546475,4.61512051684126,-0.0019826050371866064,-1.1264216662986739e-16,-2.474355894126501e-16,8.240385115516334,0.000748646048150221,0.0013504924532195418,0.0020487461585451676,4.61512051684126,3.7454460819635516e-16,1.6450589551362195e-16,-1.073415348133384e-16,4.189654742026425,-0.00014067947285729325,0.00011953110045019858,0.00018118450168624203,4.61512051684126,1.2465335328990948e-16,-3.968775412475651e-17,-2.0121679236526855e-16,6.90875477931522,0.0008129682417965193,-7.53077646287678e-05,-0.00011366418467934537,5.303304908059076,3.105561339968523,1.9652401714059267,1.5004203772081919,4.61512051684126,3.115421083399648e-17,-9.789112855704222e-20,-1.1574016922758316e-17,4.61512051684126,-1.8603660611706179,-0.7268107969347336,-0.002179543553282993,4.61512051684126,4.329292091213871e-17,-1.7100463510402525e-17,-3.8588460501402995e-17,4.61512051684126,-0.3008554957756626,-0.5232179609858989,-0.7991092454026089,4.61512051684126,2.0949802495059677e-17,1.1026142685427816e-17,-5.868293489827587e-17,5.303304908059076,1.2049985674844959,0.7662244756038687,0.586360296627033,4.61512051684126,-0.0005561537542804709,-0.0009435581307025188,-0.0014303811836443457,4.61512051684126,-0.9143323175476494,-0.3533997023053028,-0.0010582417414610927,35100.032864425,1.3717995898332447e-05,0.0,4.61512051684126,-37.0,0.0,0.0,1.0,0.0,0.0,0.0,1.0,0.5555682458318928,-0.8314709400954874
